Issue while building the feature

Traceback (most recent call last):
  File "src/unicon/eal/backend/pty_backend.py", line 484, in unicon.eal.backend.pty_backend.RawPtySpawn._read
OSError: [Errno 9] Bad file descriptor

The above exception was the direct cause of the following exception:

Traceback (most recent call last):
  File "src/unicon/statemachine/statemachine.py", line 719, in unicon.statemachine.statemachine.StateMachine.go_to
  File "src/unicon/statemachine/statetransition.py", line 481, in unicon.statemachine.statetransition.AnyStateTransition.do_transitions
  File "src/unicon/eal/backend/pty_backend.py", line 340, in unicon.eal.backend.pty_backend.RawSpawn.expect
  File "src/unicon/eal/backend/pty_backend.py", line 133, in unicon.eal.backend.pty_backend.RawSpawn.read_update_buffer
  File "src/unicon/eal/backend/pty_backend.py", line 118, in unicon.eal.backend.pty_backend.RawSpawn.read
  File "src/unicon/eal/backend/pty_backend.py", line 487, in unicon.eal.backend.pty_backend.RawPtySpawn._read
unicon.core.errors.EOF: ('Unable to read. Connection closed or not available', OSError(9, 'Bad file descriptor'))

The above exception was the direct cause of the following exception:

Traceback (most recent call last):
  File "src/genie/cli/commands/learn.py", line 365, in genie.cli.commands.learn.LearnCommand._retrieve_ops
  File "/pyats/lib/python3.6/site-packages/genie/libs/ops/ospf/iosxe/ospf.py", line 1017, in learn
    self.make(final_call=True)
  File "/pyats/lib/python3.6/site-packages/genie/ops/base/base.py", line 101, in make
    self.maker.make(*args, **kwargs)
  File "src/genie/ops/base/maker.py", line 312, in genie.ops.base.maker.Maker.make
  File "src/genie/ops/base/maker.py", line 418, in genie.ops.base.maker.Maker._call_parser
  File "src/genie/metaparser/_metaparser.py", line 272, in genie.metaparser._metaparser.MetaParser.parse
  File "/pyats/lib/python3.6/site-packages/genie/libs/parser/iosxe/show_ospf.py", line 344, in cli
    out = self.device.execute(self.cli_command)
  File "src/unicon/bases/routers/services.py", line 223, in unicon.bases.routers.services.BaseService.__call__
  File "src/unicon/bases/routers/services.py", line 154, in unicon.bases.routers.services.BaseService.pre_service
  File "src/unicon/statemachine/statemachine.py", line 722, in unicon.statemachine.statemachine.StateMachine.go_to
unicon.core.errors.StateMachineError: Failed while bringing device to "any" state
